<?xml version="1.0" encoding="utf-8"?>
<!-- =================================================================================== -->
<!-- |    This document was autogenerated by xacro from dd_bot.xacro                   | -->
<!-- |    EDITING THIS FILE BY HAND IS NOT RECOMMENDED                                 | -->
<!-- =================================================================================== -->
<robot name="dd_bot" xmlns:xacro="http://ros.org/wiki/xacro">
  <link name="base_link">
    <visual>
      <geometry>
        <box size="0.5 0.3 0.1"/>
      </geometry>
      <origin xyz="0 0 0.1"/>
    </visual>
    <inertial>
      <mass value="5.0"/>
      <inertia ixx="0.0416666666667" ixy="0.0" ixz="0.0" iyy="0.108333333333" iyz="0.0" izz="0.141666666667"/>
    </inertial>
    <collision>
      <geometry>
        <box size="0.5 0.3 0.1"/>
      </geometry>
      <origin xyz="0 0 0.1"/>
    </collision>
  </link>
  <link name="left_wheel">
    <visual>
      <geometry>
        <cylinder length="0.05" radius="0.1"/>
      </geometry>
      <origin rpy="0 1.5707 1.5707" xyz="0 0 0"/>
    </visual>
    <inertial>
      <mass value="1.0"/>
      <inertia ixx="0.00270833333333" ixy="0.0" ixz="0.0" iyy="0.005" iyz="0.0" izz="0.00270833333333"/>
    </inertial>
    <collision>
      <geometry>
        <cylinder length="0.05" radius="0.1"/>
      </geometry>
      <origin rpy="0 1.5707 1.5707" xyz="0 0 0"/>
    </collision>
  </link>
  <link name="right_wheel">
    <visual>
      <geometry>
        <cylinder length="0.05" radius="0.1"/>
      </geometry>
      <origin rpy="0 1.5707 1.5707" xyz="0 0 0"/>
    </visual>
    <inertial>
      <mass value="1.0"/>
      <inertia ixx="0.00270833333333" ixy="0.0" ixz="0.0" iyy="0.005" iyz="0.0" izz="0.00270833333333"/>
    </inertial>
    <collision>
      <geometry>
        <cylinder length="0.05" radius="0.1"/>
      </geometry>
      <origin rpy="0 1.5707 1.5707" xyz="0 0 0"/>
    </collision>
  </link>
  <link name="left_caster_wheel">
    <visual>
      <geometry>
        <sphere radius="0.025"/>
      </geometry>
      <origin xyz="0 0 0"/>
    </visual>
    <inertial>
      <mass value="1.0"/>
      <inertia ixx="0.00025" ixy="0.0" ixz="0.0" iyy="0.00025" iyz="0.0" izz="0.00025"/>
    </inertial>
    <collision>
      <geometry>
        <sphere radius="0.025"/>
      </geometry>
      <origin xyz="0 0 0"/>
    </collision>
  </link>
  <link name="right_caster_wheel">
    <visual>
      <geometry>
        <sphere radius="0.025"/>
      </geometry>
      <origin xyz="0 0 0"/>
    </visual>
    <inertial>
      <mass value="1.0"/>
      <inertia ixx="0.00025" ixy="0.0" ixz="0.0" iyy="0.00025" iyz="0.0" izz="0.00025"/>
    </inertial>
    <collision>
      <geometry>
        <sphere radius="0.025"/>
      </geometry>
      <origin xyz="0 0 0"/>
    </collision>
  </link>
  <joint name="left_caster_hinge" type="fixed">
    <child link="left_caster_wheel"/>
    <parent link="base_link"/>
    <origin rpy="0 0 0" xyz="0.225 0.125 0.025"/>
  </joint>
  <joint name="right_caster_hinge" type="fixed">
    <child link="right_caster_wheel"/>
    <parent link="base_link"/>
    <origin rpy="0 0 0" xyz="0.225 -0.125 0.025"/>
  </joint>
  <joint name="left_wheel_hinge" type="continuous">
    <child link="left_wheel"/>
    <parent link="base_link"/>
    <axis xyz="0 1 0"/>
    <origin rpy="0 0 0" xyz="-0.2 0.1775 0.1"/>
  </joint>
  <joint name="right_wheel_hinge" type="continuous">
    <child link="right_wheel"/>
    <parent link="base_link"/>
    <axis xyz="0 1 0"/>
    <origin rpy="0 0 0" xyz="-0.2 -0.1775 0.1"/>
  </joint>
  <gazebo reference="left_wheel">
    <mu1>10000000</mu1>
    <mu2>10000000</mu2>
    <minDepth>0.005</minDepth>
  </gazebo>
  <gazebo reference="right_wheel">
    <mu1>10000000</mu1>
    <mu2>10000000</mu2>
    <minDepth>0.005</minDepth>
  </gazebo>
  <gazebo reference="left_caster_wheel">
    <mu1>0.0</mu1>
    <mu2>0.0</mu2>
    <minDepth>0.005</minDepth>
  </gazebo>
  <gazebo reference="right_caster_wheel">
    <mu1>0.0</mu1>
    <mu2>0.0</mu2>
    <minDepth>0.005</minDepth>
  </gazebo>
  <gazebo>
    <plugin filename="libgazebo_ros_p3d.so" name="p3d_base_controller">
      <alwaysOn>true</alwaysOn>
      <updateRate>50.0</updateRate>
      <bodyName>base_link</bodyName>
      <topicName>ground_truth/state</topicName>
      <gaussianNoise>0.0</gaussianNoise>
      <frameName>world</frameName>
      <xyzOffsets>0 0 0</xyzOffsets>
      <rpyOffsets>0 0 0</rpyOffsets>
    </plugin>
    <plugin filename="libgazebo_ros_control.so" name="gazebo_ros_control">
      <robotNamespace>/dd_bot</robotNamespace>
    </plugin>
  </gazebo>
  <transmission name="left_wheel_tran">
    <type>transmission_interface/SimpleTransmission</type>
    <joint name="left_wheel_hinge">
      <hardwareInterface>EffortJointInterface</hardwareInterface>
    </joint>
    <actuator name="left_motor">
      <hardwareInterface>EffortJointInterface</hardwareInterface>
      <mechanicalReduction>1</mechanicalReduction>
    </actuator>
  </transmission>
  <transmission name="right_wheel_tran">
    <type>transmission_interface/SimpleTransmission</type>
    <joint name="right_wheel_hinge">
      <hardwareInterface>EffortJointInterface</hardwareInterface>
    </joint>
    <actuator name="right_motor">
      <hardwareInterface>EffortJointInterface</hardwareInterface>
      <mechanicalReduction>1</mechanicalReduction>
    </actuator>
  </transmission>
</robot>

